<?xml version="1.0" ?>

<robot name="r2d2" xmlns:xacro="http://www.ros.org/wiki/xacro">

	<material name="blue">
		<color rgba="0 0 0.8 1"/>
    </material>
    
    <material name="white">
		<color rgba="1 1 1 1"/>
    </material>

    <link name="base">
        <visual>
            <origin rpy="0 0 0" xyz="0 0 0.25"/>
            <geometry>
                <box size=".1 .1 .5"/>
            </geometry>
			<material name="white"/>
        </visual>
    </link>
   
    <joint name="lowerJoint" type="revolute">
        <axis xyz="0 0 1" />
        <limit effort="1000.0" lower="-3.14" upper="3.14" velocity="0.5" />
        <origin rpy="0 0 0" xyz="0 0 0.5"/>
        <parent link="base"/>
        <child link="lowerLink"/>
    </joint>  
    <link name="lowerLink">
        <visual>
            <origin rpy="0 0 0" xyz="0 0 0.1"/>
            <geometry>
                <cylinder radius="0.12" length="0.2"/>
            </geometry>
			<material name="blue"/>
        </visual>
    </link>
    <joint name="upperJoint" type="revolute">
        <axis xyz="1 0 0" />
        <limit effort="1000.0" lower="-3.14" upper="3.14" velocity="0.5" />
        <origin rpy="0 0 0" xyz="0 0 0.1"/>
        <parent link="lowerLink"/>
        <child link="upperLink"/>
    </joint>
    <link name="upperLink">
        <visual>
            <origin rpy="0 0 0" xyz="0 0.5 0"/>
            <geometry>
                <box size=".1 1 .1"/>
            </geometry>
			<material name="white"/>
        </visual>
    </link>
</robot>
