<?xml version="1.0" ?>

<robot name="r2d2" xmlns:xacro="http://www.ros.org/wiki/xacro">
    <link name="base_link">
        <visual>
            <origin rpy="0 0 0" xyz="0 0 0.25"/>
            <geometry>
                <box size=".1 .1 .5"/>
            </geometry>
        </visual>
    </link>
    
    <joint name="joint1" type="revolute">
        <axis xyz="0 0 1" />
        <limit effort="1000.0" lower="-3.14" upper="3.14" velocity="0.5" />
        <origin rpy="0 0 0" xyz="0 0 0.5"/>
        <parent link="base_link"/>
        <child link="link1"/>
    </joint>
    
    <link name="link1">
        <visual>
            <origin rpy="0 0 0" xyz="0 0 0.1"/>
            <geometry>
                <cylinder radius="0.12" length="0.2"/>
            </geometry>
        </visual>
    </link>
    <joint name="joint2" type="revolute">
        <axis xyz="1 0 0" />
        <limit effort="1000.0" lower="-3.14" upper="3.14" velocity="0.5" />
        <origin rpy="0 0 0" xyz="0 0 0.1"/>
        <parent link="link1"/>
        <child link="link2"/>
    </joint>


    <link name="link2">
        <visual>
            <origin rpy="0 0 0" xyz="0 0.5 0"/>
            <geometry>
                <box size=".1 1 .1"/>
            </geometry>
        </visual>
    </link>
    

    
</robot>
